Workbook

Sheet Sheet1
A1: Mass vs. Velocity Summary | AI1: Mass A – Normalized | AL1: Mass E – Normalized
AI2: t (s) | AJ2: y (m) | AL2: t (s) | AM2: y (m)
B3: Mass A — mass = 2.83 g | AI3: =B6-$B$6 -> 0 | AJ3: =C6-$C$6 -> 0 | AL3: =B84-$B$84 -> 0 | AM3: =C84-$C$84 -> 0
B4: v_term (m/s): | C4: =SLOPE(C6:C23,B6:B23) -> -9.5211122 | E4: v_term (m/s): | F4: =SLOPE(F6:F19,E6:E19) -> -9.1797924 | H4: v_term (m/s): | I4: =SLOPE(I6:I19,H6:H19) -> -8.835415 | K4: v_term (m/s): | L4: -8.8870698 | N4: v_term (m/s): | O4: -8.7834131 | AI4: =B7-$B$6 -> 0.016667 | AJ4: =C7-$C$6 -> -0.170931 | AL4: =B85-$B$84 -> 0.016667 | AM4: =C85-$C$84 -> -0.202585
B5: Trial 1 t (s) | C5: y (m) | E5: Trial 2 t (s) | F5: y (m) | H5: Trial 3 t (s) | I5: y (m) | K5: Trial 4 t (s) | L5: y (m) | N5: Trial 5 t (s) | O5: y (m) | AI5: =B8-$B$6 -> 0.033334 | AJ5: =C8-$C$6 -> -0.328368 | AL5: =B86-$B$84 -> 0.033333 | AM5: =C86-$C$84 -> -0.4012495
B6: 2.133333 | C6: 2.156881 | E6: 2.333333 | F6: 1.183994 | H6: 1.916667 | I6: 1.153114 | K6: 1.883333 | L6: 1.302849 | N6: 1.966667 | O6: 1.069565 | AI6: =B9-$B$6 -> 0.05 | AJ6: =C9-$C$6 -> -0.481306 | AL6: =B87-$B$84 -> 0.05 | AM6: =C87-$C$84 -> -0.6012206
B7: 2.15 | C7: 1.98595 | E7: 2.35 | F7: 1.027094 | H7: 1.933333 | I7: 1.006607 | K7: 1.9 | L7: 1.145295 | N7: 1.983333 | O7: 0.9169611 | AI7: =B10-$B$6 -> 0.066667 | AJ7: =C10-$C$6 -> -0.634245 | AL7: =B88-$B$84 -> 0.066667 | AM7: =C88-$C$84 -> -0.8038057
B8: 2.166667 | C8: 1.828513 | E8: 2.366667 | F8: 0.8750211 | H8: 1.95 | I8: 0.8575734 | K8: 1.916667 | L8: 0.9998611 | N8: 2 | O8: 0.7643573 | AI8: =B11-$B$6 -> 0.083334 | AJ8: =C11-$C$6 -> -0.805176 | AL8: =B89-$B$84 -> 0.083333 | AM8: =C89-$C$84 -> -1.0116188
B9: 2.183333 | C9: 1.675575 | E9: 2.383333 | F9: 0.7301901 | H9: 1.966667 | I9: 0.700962 | K9: 1.933333 | L9: 0.8453371 | N9: 2.016667 | O9: 0.6197854 | AI9: =B12-$B$6 -> 0.1 | AJ9: =C12-$C$6 -> -0.96711 | AL9: =B90-$B$84 -> 0.1 | AM9: =C90-$C$84 -> -1.21159
B10: 2.2 | C10: 1.522636 | E10: 2.4 | F10: 0.5757036 | H10: 1.983333 | I10: 0.5595066 | K10: 1.95 | L10: 0.6968729 | N10: 2.033333 | O10: 0.4671816 | AI10: =B13-$B$6 -> 0.116667 | AJ10: =C13-$C$6 -> -1.120049 | AL10: =B91-$B$84 -> 0.116667 | AM10: =C91-$C$84 -> -1.4089471
B11: 2.216667 | C11: 1.351705 | E11: 2.416667 | F11: 0.4260448 | H11: 2 | I11: 0.4180512 | K11: 1.966667 | L11: 0.5514386 | N11: 2.05 | O11: 0.3226097 | AI11: =B14-$B$6 -> 0.133334 | AJ11: =C14-$C$6 -> -1.2774854 | AL11: =B92-$B$84 -> 0.133333 | AM11: =C92-$C$84 -> -1.6180672
B12: 2.233333 | C12: 1.189771 | E12: 2.433333 | F12: 0.2739721 | H12: 2.016667 | I12: 0.2715439 | K12: 1.983333 | L12: 0.3938847 | N12: 2.066667 | O12: 0.1753604 | AI12: =B15-$B$6 -> 0.15 | AJ12: =C15-$C$6 -> -1.4439183 | AL12: =B93-$B$84 -> 0.15 | AM12: =C93-$C$84 -> -1.8245734
B13: 2.25 | C13: 1.036832 | E13: 2.45 | F13: 0.1194856 | H13: 2.033333 | I13: 0.1199845 | K13: 2 | L13: 0.2514802 | N13: 2.083333 | O13: 0.02811122 | AI13: =B16-$B$6 -> 0.166667 | AJ13: =C16-$C$6 -> -1.6013549 | AL13: =B94-$B$84 -> 0.166667 | AM13: =C94-$C$84 -> -2.0206235
B14: 2.266667 | C14: 0.8793956 | E14: 2.466667 | F14: -0.02775929 | H14: 2.05 | I14: -0.02147091 | K14: 2.016667 | L14: 0.09695623 | N14: 2.1 | O14: -0.129847 | AI14: =B17-$B$6 -> 0.183334 | AJ14: =C17-$C$6 -> -1.7542932
B15: 2.283333 | C15: 0.7129627 | E15: 2.483333 | F15: -0.1870735 | H15: 2.066667 | I15: -0.1730303 | K15: 2.033333 | L15: -0.04241835 | N15: 2.116667 | O15: -0.2610327 | AI15: =B18-$B$6 -> 0.2 | AJ15: =C18-$C$6 -> -1.916228
B16: 2.3 | C16: 0.5555261 | E16: 2.5 | F16: -0.3472918 | H16: 2.083333 | I16: -0.3220636 | K16: 2.05 | L16: -0.206032 | N16: 2.133333 | O16: -0.4082819 | AI16: =B19-$B$6 -> 0.216667 | AJ16: =C19-$C$6 -> -2.0736645
B17: 2.316667 | C17: 0.4025878 | E17: 2.516667 | F17: -0.5021215 | H17: 2.1 | I17: -0.463519 | K17: 2.066667 | L17: -0.333287 | N17: 2.15 | O17: -0.5662402 | AI17: =B20-$B$6 -> 0.233334 | AJ17: =C20-$C$6 -> -2.2311011
B18: 2.333333 | C18: 0.240653 | E18: 2.533333 | F18: -0.6483496 | H18: 2.116667 | I18: -0.6201304 | K18: 2.083333 | L18: -0.4817513 | N18: 2.166667 | O18: -0.7001031 | AI18: =B21-$B$6 -> 0.25 | AJ18: =C21-$C$6 -> -2.3885376
B19: 2.35 | C19: 0.08321646 | E19: 2.55 | F19: -0.8096306 | H19: 2.133333 | I19: -0.7641118 | K19: 2.1 | L19: -0.6332454 | N19: 2.183333 | O19: -0.8152253 | AI19: =B22-$B$6 -> 0.266667 | AJ19: =C22-$C$6 -> -2.5324796
B20: 2.366667 | C20: -0.07422009 | K20: 2.116667 | L20: -0.7665602 | AI20: =B23-$B$6 -> 0.283334 | AJ20: =C23-$C$6 -> -2.7079089
B21: 2.383333 | C21: -0.2316566
B22: 2.4 | C22: -0.3755986
B23: 2.416667 | C23: -0.5510279
B26: Mass B — mass = 3.92 g
B27: v_term (m/s): | C27: =SLOPE(C29:C42,B29:B42) -> -9.5334844 | E27: v_term (m/s): | F27: =SLOPE(F29:F42,E29:E42) -> -10.025588 | H27: v_term (m/s): | I27: -9.4621 | K27: v_term (m/s): | L27: =SLOPE(L29:L42,K29:K42) -> -10.210334 | N27: v_term (m/s): | O27: -10.007525
B28: Trial 1 t (s) | C28: y (m) | E28: Trial 2 t (s) | F28: y (m) | H28: Trial 3 t (s) | I28: y (m) | K28: Trial 4 t (s) | L28: y (m) | N28: Trial 5 t (s) | O28: y (m)
B29: 2.416667 | C29: 1.275267 | E29: 1.95 | F29: 1.475215 | H29: 1.783333 | I29: 1.183428 | N29: 1.833333 | O29: 1.001364
B30: 2.433333 | C30: 1.116227 | E30: 1.966667 | F30: 1.285273 | H30: 1.8 | I30: 1.01859 | K30: 1.95 | L30: 1.281579 | N30: 1.85 | O30: 0.840382
B31: 2.45 | C31: 0.9454056 | E31: 1.983333 | F31: 1.120657 | H31: 1.816667 | I31: 0.8680863 | K31: 1.966667 | L31: 1.104677 | N31: 1.866667 | O31: 0.6739427
B32: 2.466667 | C32: 0.7922558 | E32: 2 | F32: 0.9528751 | H32: 1.833333 | I32: 0.7086236 | K32: 1.983333 | L32: 0.9316205 | N32: 1.883333 | O32: 0.5102319
B33: 2.483333 | C33: 0.6332156 | E33: 2.016667 | F33: 0.7850931 | H33: 1.85 | I33: 0.5437858 | K33: 2 | L33: 0.7701012 | N33: 1.9 | O33: 0.3410641
B34: 2.5 | C34: 0.4771206 | E34: 2.033333 | F34: 0.6236425 | H34: 1.866667 | I34: 0.3950733 | K34: 2.016667 | L34: 0.5951219 | N34: 1.916667 | O34: 0.1773533
B35: 2.516667 | C35: 0.3180804 | E35: 2.05 | F35: 0.4558605 | H35: 1.883333 | I35: 0.2266521 | K35: 2.033333 | L35: 0.4201426 | N35: 1.933333 | O35: 0.01091405
B36: 2.533333 | C36: 0.1590402 | E36: 2.066667 | F36: 0.2849128 | H36: 1.9 | I36: 0.07256449 | K36: 2.05 | L36: 0.2451633 | N36: 1.95 | O36: -0.1609823
B37: 2.55 | C37: 0.005890377 | E37: 2.083333 | F37: 0.1171308 | H37: 1.916667 | I37: -0.08152307 | K37: 2.066667 | L37: 0.07979825 | N37: 1.966667 | O37: -0.324693
B38: 2.566667 | C38: -0.156095 | E38: 2.1 | F38: -0.04748547 | H38: 1.933333 | I38: -0.2427775 | K38: 2.083333 | L38: -0.09133535 | N38: 1.983333 | O38: -0.4938608
B39: 2.583333 | C39: -0.3239708 | E39: 2.116667 | F39: -0.2152675 | H39: 1.95 | I39: -0.4111988 | K39: 2.1 | L39: -0.2624689 | N39: 2 | O39: -0.6575716
B40: 2.6 | C40: -0.4741754 | E40: 2.133333 | F40: -0.3862152 | H40: 1.966667 | I40: -0.5724532 | K40: 2.116667 | L40: -0.427834 | N40: 2.016667 | O40: -0.834925
B41: 2.616667 | C41: -0.639106 | E41: 2.15 | F41: -0.5476657 | H41: 1.983333 | I41: -0.7211656 | K41: 2.133333 | L41: -0.5893533
B42: 2.633333 | C42: -0.7922558 | E42: 2.166667 | F42: -0.6996193 | H42: 2 | I42: -0.8394189 | K42: 2.15 | L42: -0.7604869
...

Sheet Vt model
A1: Terminal-velocity model — quadratic drag, ball dropped from rest
A3: Forward model (explicit): v(h) = v_t · √(1 − exp(−2·g·h / v_t²)) = speed after falling height h
A4: g and h are linked from Sheet1 constants. The table below is the model curve; Sheet1 looks up the measured v in column B and reads off v_t from column A — exact inversion, no iteration.
A6: v_t grid start (m/s) | B6: 6
A7: v_t grid step (m/s) | B7: 0.01
A9: v_t (m/s) | B9: predicted v after falling h (m/s)
A10: =$B$6 -> 6 | B10: =A10*SQRT(1-EXP(-2*Sheet1!$M$103*Sheet1!$M$105/A10^2)) -> 5.995665
A11: =A10+$B$7 -> 6.01 | B11: =A11*SQRT(1-EXP(-2*Sheet1!$M$103*Sheet1!$M$105/A11^2)) -> 6.0055622
A12: =A11+$B$7 -> 6.02 | B12: =A12*SQRT(1-EXP(-2*Sheet1!$M$103*Sheet1!$M$105/A12^2)) -> 6.0154576
A13: =A12+$B$7 -> 6.03 | B13: =A13*SQRT(1-EXP(-2*Sheet1!$M$103*Sheet1!$M$105/A13^2)) -> 6.025351
A14: =A13+$B$7 -> 6.04 | B14: =A14*SQRT(1-EXP(-2*Sheet1!$M$103*Sheet1!$M$105/A14^2)) -> 6.0352424
A15: =A14+$B$7 -> 6.05 | B15: =A15*SQRT(1-EXP(-2*Sheet1!$M$103*Sheet1!$M$105/A15^2)) -> 6.0451318
A16: =A15+$B$7 -> 6.06 | B16: =A16*SQRT(1-EXP(-2*Sheet1!$M$103*Sheet1!$M$105/A16^2)) -> 6.0550192
A17: =A16+$B$7 -> 6.07 | B17: =A17*SQRT(1-EXP(-2*Sheet1!$M$103*Sheet1!$M$105/A17^2)) -> 6.0649045
A18: =A17+$B$7 -> 6.08 | B18: =A18*SQRT(1-EXP(-2*Sheet1!$M$103*Sheet1!$M$105/A18^2)) -> 6.0747877
A19: =A18+$B$7 -> 6.09 | B19: =A19*SQRT(1-EXP(-2*Sheet1!$M$103*Sheet1!$M$105/A19^2)) -> 6.0846689
A20: =A19+$B$7 -> 6.1 | B20: =A20*SQRT(1-EXP(-2*Sheet1!$M$103*Sheet1!$M$105/A20^2)) -> 6.0945478
A21: =A20+$B$7 -> 6.11 | B21: =A21*SQRT(1-EXP(-2*Sheet1!$M$103*Sheet1!$M$105/A21^2)) -> 6.1044247
A22: =A21+$B$7 -> 6.12 | B22: =A22*SQRT(1-EXP(-2*Sheet1!$M$103*Sheet1!$M$105/A22^2)) -> 6.1142993
... A1210: =A1209+$B$7 -> 18 | B1210: =A1210*SQRT(1-EXP(-2*Sheet1!$M$103*Sheet1!$M$105/A1210^2)) -> 12.936002
